
  0%|                                                                                  | 0/415716 [00:00<?, ?it/s]Traceback (most recent call last):
  File "/home/ubuntu/ejpark/tevatron/src/tevatron/retriever/driver/train.py", line 107, in <module>
    if trainer.is_world_process_zero():
  File "/home/ubuntu/ejpark/tevatron/src/tevatron/retriever/driver/train.py", line 100, in main
    train_dataset=train_dataset,
  File "/home/ubuntu/ejpark/con_venv/lib/python3.9/site-packages/transformers/trainer.py", line 1780, in train
    return inner_training_loop(
  File "/home/ubuntu/ejpark/con_venv/lib/python3.9/site-packages/transformers/trainer.py", line 2085, in _inner_training_loop
    for step, inputs in enumerate(epoch_iterator):
  File "/home/ubuntu/ejpark/con_venv/lib/python3.9/site-packages/accelerate/data_loader.py", line 452, in __iter__
    current_batch = next(dataloader_iter)
  File "/home/ubuntu/ejpark/con_venv/lib/python3.9/site-packages/torch/utils/data/dataloader.py", line 630, in __next__
    data = self._next_data()
  File "/home/ubuntu/ejpark/con_venv/lib/python3.9/site-packages/torch/utils/data/dataloader.py", line 1345, in _next_data
    return self._process_data(data)
  File "/home/ubuntu/ejpark/con_venv/lib/python3.9/site-packages/torch/utils/data/dataloader.py", line 1371, in _process_data
    data.reraise()
  File "/home/ubuntu/ejpark/con_venv/lib/python3.9/site-packages/torch/_utils.py", line 694, in reraise
    raise exception
NameError: Caught NameError in DataLoader worker process 0.
Original Traceback (most recent call last):
  File "/home/ubuntu/ejpark/con_venv/lib/python3.9/site-packages/torch/utils/data/_utils/worker.py", line 308, in _worker_loop
    data = fetcher.fetch(index)
  File "/home/ubuntu/ejpark/con_venv/lib/python3.9/site-packages/torch/utils/data/_utils/fetch.py", line 51, in fetch
    data = [self.dataset[idx] for idx in possibly_batched_index]
  File "/home/ubuntu/ejpark/con_venv/lib/python3.9/site-packages/torch/utils/data/_utils/fetch.py", line 51, in <listcomp>
    data = [self.dataset[idx] for idx in possibly_batched_index]
  File "/home/ubuntu/ejpark/tevatron/src/tevatron/retriever/fine_dataset.py", line 211, in __getitem__
    else :
NameError: name 'item' is not defined